<mujoco model="base">
  <compiler angle="radian" meshdir="!!! This spec should be loaded with asset dict. See simulator.mujoco.transforms.load_model_from_spec !!!/" texturedir="!!! This spec should be loaded with asset dict. See simulator.mujoco.transforms.load_model_from_spec !!!/"/>

  <option impratio="20" density="1.2" viscosity="2e-05" cone="elliptic"/>

  <size njmax="5000" nconmax="5000"/>

  <visual>
    <global azimuth="120" elevation="-20" offwidth="1920" offheight="1080"/>
    <map znear="0.001"/>
  </visual>

  <default>
    <default class="main_ph">
      <default class="panda_ph">
        <material shininess="0.25"/>
        <joint range="-2.8973 2.8973" armature="0.1" damping="1"/>
        <general ctrlrange="-2.8973 2.8973" forcerange="-100 100" biastype="affine" biasprm="0 -1"/>
        <default class="finger_ph">
          <joint type="slide" range="0 0.04"/>
        </default>
        <default class="visual_ph">
          <geom type="mesh" contype="0" conaffinity="0" group="2"/>
        </default>
        <default class="collision_ph">
          <geom type="mesh" contype="0" conaffinity="0" group="3"/>
          <default class="primitive_collision_ph">
            <geom type="box" solref="0.01" solimp="0.99 0.995 0.01"/>
            <default class="fingertip_pad_collision_1_ph">
              <geom size="0.011 0.0075 0.01"/>
            </default>
            <default class="fingertip_pad_collision_2_ph">
              <geom size="0.011 0.0044 0.0019"/>
            </default>
            <default class="fingertip_pad_collision_3_ph">
              <geom size="0.00875 0.0035 0.01175"/>
            </default>
            <default class="fingertip_pad_collision_4_ph">
              <geom size="0.00875 0.0076 0.00825" conaffinity="3"/>
            </default>
          </default>
        </default>
      </default>
    </default>
  </default>

  <custom>
    <text name="model_suffix" data="_ph"/>
    <text name="initial_ctrl" data="0.3314,-0.4919,-0.5844,-2.0910,-0.2424,1.7946,0.6114,0.0000"/>
    <text name="relative_assets_path" data="franka_table.assets.pkl"/>
  </custom>

  <asset>
    <texture type="skybox" builtin="gradient" rgb1="0.9 0.9 1" rgb2="0.2 0.3 0.4" width="256" height="1536"/>
    <texture type="2d" name="texplane" file="texplane.png"/>
    <texture type="cube" name="tex-ceramic" file="tex-ceramic.png"/>
    <texture type="cube" name="tex-steel-brushed" file="tex-steel-brushed.png"/>
    <texture type="2d" name="tex-light-gray-plaster" file="tex-light-gray-plaster.png"/>
    <texture type="cube" name="textable" builtin="flat" rgb1="0.5 0.5 0.5" width="512" height="3072"/>
    <material name="floorplane" texture="texplane" texuniform="true" texrepeat="2 2" specular="0" shininess="0" reflectance="0.01"/>
    <material name="table_ceramic" texture="tex-ceramic" specular="0.2" shininess="0"/>
    <material name="table_legs_metal" texture="tex-steel-brushed" shininess="0.8" reflectance="0.8"/>
    <material name="walls_mat" texture="tex-light-gray-plaster" texuniform="true" texrepeat="3 3" specular="0.1" shininess="0.1"/>
    <material name="table_mat" texture="textable"/>
    <material name="white_ph" class="panda_ph"/>
    <material name="off_white_ph" class="panda_ph" rgba="0.901961 0.921569 0.929412 1"/>
    <material name="black_ph" class="panda_ph" rgba="0.25 0.25 0.25 1"/>
    <material name="green_ph" class="panda_ph" rgba="0 1 0 1"/>
    <material name="light_blue_ph" class="panda_ph" rgba="0.039216 0.541176 0.780392 1"/>
    <mesh name="link0_c_ph" file="link0_c.stl"/>
    <mesh name="link1_c_ph" file="link1_c.stl"/>
    <mesh name="link2_c_ph" file="link2_c.stl"/>
    <mesh name="link3_c_ph" file="link3_c.stl"/>
    <mesh name="link4_c_ph" file="link4_c.stl"/>
    <mesh name="link5_c0_ph" file="link5_c0.obj"/>
    <mesh name="link5_c1_ph" file="link5_c1.obj"/>
    <mesh name="link5_c2_ph" file="link5_c2.obj"/>
    <mesh name="link6_c_ph" file="link6_c.stl"/>
    <mesh name="link7_c_ph" file="link7_c.stl"/>
    <mesh name="hand_c_ph" file="hand_c.stl"/>
    <mesh name="link0_0_ph" file="link0_0.obj"/>
    <mesh name="link0_1_ph" file="link0_1.obj"/>
    <mesh name="link0_2_ph" file="link0_2.obj"/>
    <mesh name="link0_3_ph" file="link0_3.obj"/>
    <mesh name="link0_4_ph" file="link0_4.obj"/>
    <mesh name="link0_5_ph" file="link0_5.obj"/>
    <mesh name="link0_7_ph" file="link0_7.obj"/>
    <mesh name="link0_8_ph" file="link0_8.obj"/>
    <mesh name="link0_9_ph" file="link0_9.obj"/>
    <mesh name="link0_10_ph" file="link0_10.obj"/>
    <mesh name="link0_11_ph" file="link0_11.obj"/>
    <mesh name="link1_ph" file="link1.obj"/>
    <mesh name="link2_ph" file="link2.obj"/>
    <mesh name="link3_0_ph" file="link3_0.obj"/>
    <mesh name="link3_1_ph" file="link3_1.obj"/>
    <mesh name="link3_2_ph" file="link3_2.obj"/>
    <mesh name="link3_3_ph" file="link3_3.obj"/>
    <mesh name="link4_0_ph" file="link4_0.obj"/>
    <mesh name="link4_1_ph" file="link4_1.obj"/>
    <mesh name="link4_2_ph" file="link4_2.obj"/>
    <mesh name="link4_3_ph" file="link4_3.obj"/>
    <mesh name="link5_0_ph" file="link5_0.obj"/>
    <mesh name="link5_1_ph" file="link5_1.obj"/>
    <mesh name="link5_2_ph" file="link5_2.obj"/>
    <mesh name="link6_0_ph" file="link6_0.obj"/>
    <mesh name="link6_1_ph" file="link6_1.obj"/>
    <mesh name="link6_2_ph" file="link6_2.obj"/>
    <mesh name="link6_3_ph" file="link6_3.obj"/>
    <mesh name="link6_4_ph" file="link6_4.obj"/>
    <mesh name="link6_5_ph" file="link6_5.obj"/>
    <mesh name="link6_6_ph" file="link6_6.obj"/>
    <mesh name="link6_7_ph" file="link6_7.obj"/>
    <mesh name="link6_8_ph" file="link6_8.obj"/>
    <mesh name="link6_9_ph" file="link6_9.obj"/>
    <mesh name="link6_10_ph" file="link6_10.obj"/>
    <mesh name="link6_11_ph" file="link6_11.obj"/>
    <mesh name="link6_12_ph" file="link6_12.obj"/>
    <mesh name="link6_13_ph" file="link6_13.obj"/>
    <mesh name="link6_14_ph" file="link6_14.obj"/>
    <mesh name="link6_15_ph" file="link6_15.obj"/>
    <mesh name="link6_16_ph" file="link6_16.obj"/>
    <mesh name="link7_0_ph" file="link7_0.obj"/>
    <mesh name="link7_1_ph" file="link7_1.obj"/>
    <mesh name="link7_2_ph" file="link7_2.obj"/>
    <mesh name="link7_3_ph" file="link7_3.obj"/>
    <mesh name="link7_4_ph" file="link7_4.obj"/>
    <mesh name="link7_5_ph" file="link7_5.obj"/>
    <mesh name="link7_6_ph" file="link7_6.obj"/>
    <mesh name="link7_7_ph" file="link7_7.obj"/>
    <mesh name="hand_0_ph" file="hand_0.obj"/>
    <mesh name="hand_1_ph" file="hand_1.obj"/>
    <mesh name="hand_2_ph" file="hand_2.obj"/>
    <mesh name="hand_3_ph" file="hand_3.obj"/>
    <mesh name="hand_4_ph" file="hand_4.obj"/>
    <mesh name="finger_0_ph" file="finger_0.obj"/>
    <mesh name="finger_1_ph" file="finger_1.obj"/>
  </asset>

  <worldbody>
    <geom name="floor" size="3 3 0.125" pos="0.8 0 0" type="plane" group="1" material="floorplane"/>
    <geom name="wall_leftcorner_visual" size="1.06 1.5 0.01" pos="-0.45 2.25 1.5" quat="0.653281 0.653281 0.270598 0.270598" type="box" contype="0" conaffinity="0" group="1" material="walls_mat"/>
    <geom name="wall_rightcorner_visual" size="1.06 1.5 0.01" pos="-0.45 -2.25 1.5" quat="0.653281 0.653281 -0.270598 -0.270598" type="box" contype="0" conaffinity="0" group="1" material="walls_mat"/>
    <geom name="wall_left_visual" size="1.75 1.5 0.01" pos="2.05 3 1.5" quat="0.707107 0.707107 0 0" type="box" contype="0" conaffinity="0" group="1" material="walls_mat"/>
    <geom name="wall_right_visual" size="1.75 1.5 0.01" pos="2.05 -3 1.5" quat="0.707107 -0.707107 0 0" type="box" contype="0" conaffinity="0" group="1" material="walls_mat"/>
    <geom name="wall_rear_visual" size="1.5 1.5 0.01" pos="-1.2 0 1.5" quat="0.5 0.5 0.5 0.5" type="box" contype="0" conaffinity="0" group="1" material="walls_mat"/>
    <geom name="wall_front_visual" size="3 1.5 0.01" pos="3.8 0 1.5" quat="0.5 0.5 -0.5 -0.5" type="box" contype="0" conaffinity="0" group="1" material="walls_mat"/>
    <site name="origin" pos="0 0 0"/>
    <camera name="frontview" pos="2.4 0 1.45" quat="0.560842 0.430646 0.430646 0.560842"/>
    <camera name="birdview" pos="0.6 0 3" quat="0.707107 0 0 0.707107"/>
    <camera name="agentview" pos="1.3 0 1.35" quat="0.653098 0.271041 0.271041 0.653098"/>
    <camera name="sideview" pos="0.743482 1.27612 1.48796" quat="0.00990507 0.00687796 0.591223 0.806418"/>
    <light pos="1.8 3 1.5" dir="-0.707107 -0.707107 0" castshadow="false"/>
    <body name="table" pos="0.5 0 0.275">
      <geom name="table_collision" size="0.2 0.3 0.025" type="box" rgba="0.5 0.5 0 1"/>
      <geom name="table_visual" size="0.2 0.3 0.025" type="box" contype="0" conaffinity="0" group="1" material="table_ceramic"/>
      <geom name="table_leg1_visual" size="0.025 0.1375" pos="0 0.2 -0.1375" type="cylinder" contype="0" conaffinity="0" group="1" material="table_legs_metal"/>
      <geom name="table_leg2_visual" size="0.025 0.1375" pos="0 0.2 -0.1375" type="cylinder" contype="0" conaffinity="0" group="1" material="table_legs_metal"/>
      <geom name="table_leg3_visual" size="0.025 0.1375" pos="0 -0.2 -0.1375" type="cylinder" contype="0" conaffinity="0" group="1" material="table_legs_metal"/>
      <geom name="table_leg4_visual" size="0.025 0.1375" pos="0 -0.2 -0.1375" type="cylinder" contype="0" conaffinity="0" group="1" material="table_legs_metal"/>
      <site name="table_top" pos="0 0 0.025" size="0.001" rgba="0 0 0 0"/>
    </body>
    <body name="left_eef_target" pos="0.8 0 -1" mocap="true">
      <geom name="left_eef_target_box" size="0.05 0.05 0.05" type="box" contype="0" conaffinity="0" group="2" rgba="0.898 0.42 0.435 0.5"/>
      <geom name="left_eef_target_sphere" size="0.01" contype="0" conaffinity="0" group="2" rgba="0.898 0.42 0.435 0.8"/>
    </body>
    <body name="right_eef_target" pos="0.8 0 -1" mocap="true">
      <geom name="right_eef_target_box" size="0.05 0.05 0.05" type="box" contype="0" conaffinity="0" group="2" rgba="0.208 0.314 0.439 0.5"/>
      <geom name="right_eef_target_sphere" size="0.01" contype="0" conaffinity="0" group="2" rgba="0.208 0.314 0.439 0.8"/>
    </body>
    <body name="world_ph">
      <light name="top_ph" pos="0 0 2" dir="0 0 -1" mode="trackcom"/>
      <body name="link0_ph" childclass="panda_ph">
        <inertial pos="-0.041018 -0.00014 0.049974" quat="0.00630474 0.751245 0.00741774 0.659952" mass="0.629769" diaginertia="0.00430465 0.00387984 0.00313051"/>
        <geom class="visual_ph" material="off_white_ph" mesh="link0_0_ph"/>
        <geom class="visual_ph" material="black_ph" mesh="link0_1_ph"/>
        <geom class="visual_ph" material="off_white_ph" mesh="link0_2_ph"/>
        <geom class="visual_ph" material="black_ph" mesh="link0_3_ph"/>
        <geom class="visual_ph" material="off_white_ph" mesh="link0_4_ph"/>
        <geom class="visual_ph" material="black_ph" mesh="link0_5_ph"/>
        <geom class="visual_ph" material="white_ph" mesh="link0_7_ph"/>
        <geom class="visual_ph" material="white_ph" mesh="link0_8_ph"/>
        <geom class="visual_ph" material="black_ph" mesh="link0_9_ph"/>
        <geom class="visual_ph" material="off_white_ph" mesh="link0_10_ph"/>
        <geom class="visual_ph" material="white_ph" mesh="link0_11_ph"/>
        <geom class="collision_ph" mesh="link0_c_ph"/>
        <body name="link1_ph" pos="0 0 0.333">
          <inertial pos="0.003875 0.002081 -0.04762" quat="0.711549 0.00634377 -0.0131124 0.702485" mass="4.97068" diaginertia="0.707137 0.703435 0.00852456"/>
          <joint name="joint1_ph" pos="0 0 0" axis="0 0 1" damping="40"/>
          <geom class="visual_ph" material="white_ph" mesh="link1_ph"/>
          <geom class="collision_ph" mesh="link1_c_ph"/>
          <site name="site_joint1_ph" pos="0 0 0"/>
          <body name="link2_ph" quat="0.707107 -0.707107 0 0">
            <inertial pos="-0.003141 -0.02872 0.003495" quat="-0.168175 0.828366 -0.122878 0.520027" mass="0.646926" diaginertia="0.0310326 0.0283001 0.00273425"/>
            <joint name="joint2_ph" pos="0 0 0" axis="0 0 1" range="-1.7628 1.7628" damping="40"/>
            <geom class="visual_ph" material="white_ph" mesh="link2_ph"/>
            <geom class="collision_ph" mesh="link2_c_ph"/>
            <site name="site_joint2_ph" pos="0 0 0"/>
            <body name="link3_ph" pos="0 -0.316 0" quat="0.707107 0.707107 0 0">
              <inertial pos="0.027518 0.039252 -0.066502" quat="0.662769 -0.00678331 0.252053 0.705096" mass="3.2286" diaginertia="0.0415014 0.0414793 0.00124635"/>
              <joint name="joint3_ph" pos="0 0 0" axis="0 0 1" damping="40"/>
              <geom class="visual_ph" material="white_ph" mesh="link3_0_ph"/>
              <geom class="visual_ph" material="white_ph" mesh="link3_1_ph"/>
              <geom class="visual_ph" material="white_ph" mesh="link3_2_ph"/>
              <geom class="visual_ph" material="black_ph" mesh="link3_3_ph"/>
              <geom class="collision_ph" mesh="link3_c_ph"/>
              <site name="site_joint3_ph" pos="0 0 0"/>
              <body name="link4_ph" pos="0.0825 0 0" quat="0.707107 0.707107 0 0">
                <inertial pos="-0.05317 0.104419 0.027454" quat="0.65058 0.529822 -0.0962034 0.535518" mass="3.5879" diaginertia="0.0349596 0.0281483 0.0106201"/>
                <joint name="joint4_ph" pos="0 0 0" axis="0 0 1" range="-3.0718 -0.0698" damping="40"/>
                <geom class="visual_ph" material="white_ph" mesh="link4_0_ph"/>
                <geom class="visual_ph" material="white_ph" mesh="link4_1_ph"/>
                <geom class="visual_ph" material="black_ph" mesh="link4_2_ph"/>
                <geom class="visual_ph" material="white_ph" mesh="link4_3_ph"/>
                <geom class="collision_ph" mesh="link4_c_ph"/>
                <site name="site_joint4_ph" pos="0 0 0"/>
                <body name="link5_ph" pos="-0.0825 0.384 0" quat="0.707107 -0.707107 0 0">
                  <inertial pos="-0.011953 0.041065 -0.038437" quat="0.987313 -0.0121954 0.0719187 -0.141037" mass="1.22595" diaginertia="0.0367625 0.0288531 0.00803437"/>
                  <joint name="joint5_ph" pos="0 0 0" axis="0 0 1" damping="2"/>
                  <geom class="visual_ph" material="black_ph" mesh="link5_0_ph"/>
                  <geom class="visual_ph" material="white_ph" mesh="link5_1_ph"/>
                  <geom class="visual_ph" material="white_ph" mesh="link5_2_ph"/>
                  <geom class="collision_ph" mesh="link5_c0_ph"/>
                  <geom class="collision_ph" mesh="link5_c1_ph"/>
                  <geom class="collision_ph" mesh="link5_c2_ph"/>
                  <site name="site_joint5_ph" pos="0 0 0"/>
                  <body name="link6_ph" quat="0.707107 0.707107 0 0">
                    <inertial pos="0.060149 -0.014117 -0.010517" quat="0.101075 0.59332 0.0287227 0.798079" mass="1.66656" diaginertia="0.00584276 0.00431037 0.00159787"/>
                    <joint name="joint6_ph" pos="0 0 0" axis="0 0 1" range="-0.0175 3.7525" damping="2"/>
                    <geom class="visual_ph" material="off_white_ph" mesh="link6_0_ph"/>
                    <geom class="visual_ph" material="white_ph" mesh="link6_1_ph"/>
                    <geom class="visual_ph" material="black_ph" mesh="link6_2_ph"/>
                    <geom class="visual_ph" material="white_ph" mesh="link6_3_ph"/>
                    <geom class="visual_ph" material="white_ph" mesh="link6_4_ph"/>
                    <geom class="visual_ph" material="white_ph" mesh="link6_5_ph"/>
                    <geom class="visual_ph" material="white_ph" mesh="link6_6_ph"/>
                    <geom class="visual_ph" material="light_blue_ph" mesh="link6_7_ph"/>
                    <geom class="visual_ph" material="light_blue_ph" mesh="link6_8_ph"/>
                    <geom class="visual_ph" material="black_ph" mesh="link6_9_ph"/>
                    <geom class="visual_ph" material="black_ph" mesh="link6_10_ph"/>
                    <geom class="visual_ph" material="white_ph" mesh="link6_11_ph"/>
                    <geom class="visual_ph" material="green_ph" mesh="link6_12_ph"/>
                    <geom class="visual_ph" material="white_ph" mesh="link6_13_ph"/>
                    <geom class="visual_ph" material="black_ph" mesh="link6_14_ph"/>
                    <geom class="visual_ph" material="black_ph" mesh="link6_15_ph"/>
                    <geom class="visual_ph" material="white_ph" mesh="link6_16_ph"/>
                    <geom class="collision_ph" mesh="link6_c_ph"/>
                    <site name="site_joint6_ph" pos="0 0 0"/>
                    <body name="link7_ph" pos="0.088 0 0" quat="0.707107 0.707107 0 0">
                      <inertial pos="0.010517 -0.004252 0.061597" quat="0.992939 -0.0762041 0.0733595 -0.0537067" mass="0.735522" diaginertia="0.0127345 0.0101055 0.00451803"/>
                      <joint name="joint7_ph" pos="0 0 0" axis="0 0 1" damping="2"/>
                      <geom class="visual_ph" material="white_ph" mesh="link7_0_ph"/>
                      <geom class="visual_ph" material="black_ph" mesh="link7_1_ph"/>
                      <geom class="visual_ph" material="black_ph" mesh="link7_2_ph"/>
                      <geom class="visual_ph" material="black_ph" mesh="link7_3_ph"/>
                      <geom class="visual_ph" material="black_ph" mesh="link7_4_ph"/>
                      <geom class="visual_ph" material="black_ph" mesh="link7_5_ph"/>
                      <geom class="visual_ph" material="black_ph" mesh="link7_6_ph"/>
                      <geom class="visual_ph" material="white_ph" mesh="link7_7_ph"/>
                      <geom class="collision_ph" mesh="link7_c_ph"/>
                      <site name="site_joint7_ph" pos="0 0 0"/>
                      <body name="hand_ph" pos="0 0 0.107" quat="0.92388 0 0 -0.382683">
                        <inertial pos="-0.01 0 0.03" mass="0.73" diaginertia="0.001 0.0025 0.0017"/>
                        <geom class="visual_ph" material="off_white_ph" mesh="hand_0_ph"/>
                        <geom class="visual_ph" material="black_ph" mesh="hand_1_ph"/>
                        <geom class="visual_ph" material="black_ph" mesh="hand_2_ph"/>
                        <geom class="visual_ph" material="white_ph" mesh="hand_3_ph"/>
                        <geom class="visual_ph" material="off_white_ph" mesh="hand_4_ph"/>
                        <geom class="collision_ph" mesh="hand_c_ph"/>
                        <geom name="hand_capsule_ph" class="collision_ph" size="0.04 0.06" pos="0 0 0.03" quat="0.707107 0.707107 0 0" type="capsule" conaffinity="1"/>
                        <site name="end_effector_ph" pos="0 0 0.0584" size="0.01" rgba="1 0 0 1"/>
                        <site name="gripper_ph" pos="0 0 0.1"/>
                        <camera name="handcam_left_ph" pos="0.05 -0.05 0.01" quat="0 0.707105 0.707108 0" fovy="105"/>
                        <camera name="handcam_front_ph" pos="0.05 0 0.01" quat="0 0.707105 0.707108 0" fovy="105"/>
                        <camera name="handcam_back_ph" pos="-0.05 0 0.01" quat="0 0.707105 0.707108 0" fovy="105"/>
                        <camera name="handcam_right_ph" pos="0.05 0.05 0.01" quat="0 0.707105 0.707108 0" fovy="105"/>
                        <body name="left_finger_ph" pos="0 0 0.0584">
                          <inertial pos="0 0 0" mass="0.015" diaginertia="2.375e-06 2.375e-06 7.5e-07"/>
                          <joint name="finger_joint1_ph" class="finger_ph" pos="0 0 0" axis="0 1 0" damping="10"/>
                          <geom class="visual_ph" material="off_white_ph" mesh="finger_0_ph"/>
                          <geom class="visual_ph" material="black_ph" mesh="finger_1_ph"/>
                          <geom class="collision_ph" mesh="finger_0_ph"/>
                          <geom class="fingertip_pad_collision_1_ph" pos="0 0.0185 0.011"/>
                          <geom class="fingertip_pad_collision_2_ph" pos="0 0.0068 0.0022"/>
                          <geom class="fingertip_pad_collision_3_ph" pos="0 0.0159 0.02835" quat="0.970143 0.242536 0 0"/>
                          <geom name="left_finger_pad_ph" class="fingertip_pad_collision_4_ph" pos="0 0.00758 0.04525"/>
                        </body>
                        <body name="right_finger_ph" pos="0 0 0.0584" quat="0 0 0 1">
                          <inertial pos="0 0 0" mass="0.015" diaginertia="2.375e-06 2.375e-06 7.5e-07"/>
                          <joint name="finger_joint2_ph" class="finger_ph" pos="0 0 0" axis="0 1 0" damping="10"/>
                          <geom class="visual_ph" material="off_white_ph" mesh="finger_0_ph"/>
                          <geom class="visual_ph" material="black_ph" mesh="finger_1_ph"/>
                          <geom class="collision_ph" mesh="finger_0_ph"/>
                          <geom class="fingertip_pad_collision_1_ph" pos="0 0.0185 0.011"/>
                          <geom class="fingertip_pad_collision_2_ph" pos="0 0.0068 0.0022"/>
                          <geom class="fingertip_pad_collision_3_ph" pos="0 0.0159 0.02835" quat="0.970143 0.242536 0 0"/>
                          <geom name="right_finger_pad_ph" class="fingertip_pad_collision_4_ph" pos="0 0.00758 0.04525"/>
                        </body>
                      </body>
                    </body>
                  </body>
                </body>
              </body>
            </body>
          </body>
        </body>
      </body>
    </body>
  </worldbody>

  <equality>
    <joint joint1="finger_joint1_ph" joint2="finger_joint2_ph" polycoef="0 1 0 0 0" solref="0.005" solimp="0.95 0.99"/>
  </equality>

  <actuator>
    <general name="actuator1_ph" class="panda_ph" joint="joint1_ph" gainprm="1000" biasprm="0 -1000 -20"/>
    <general name="actuator2_ph" class="panda_ph" joint="joint2_ph" ctrlrange="-1.7628 1.7628" gainprm="1000" biasprm="0 -1000 -20"/>
    <general name="actuator3_ph" class="panda_ph" joint="joint3_ph" gainprm="750" biasprm="0 -750 -4"/>
    <general name="actuator4_ph" class="panda_ph" joint="joint4_ph" ctrlrange="-3.0718 -0.0698" gainprm="750" biasprm="0 -750 -4"/>
    <general name="actuator5_ph" class="panda_ph" joint="joint5_ph" forcerange="-12 12" gainprm="300" biasprm="0 -300 -2"/>
    <general name="actuator6_ph" class="panda_ph" joint="joint6_ph" ctrlrange="-0.0175 3.7525" forcerange="-12 12" gainprm="300" biasprm="0 -300 -2"/>
    <general name="actuator7_ph" class="panda_ph" joint="joint7_ph" forcerange="-12 12" gainprm="300" biasprm="0 -300 -2"/>
    <general name="actuator8_ph" class="panda_ph" joint="finger_joint1_ph" ctrlrange="0 0.04" forcerange="-200 200" gainprm="350" biasprm="0 -350 -10"/>
  </actuator>

  <sensor>
    <torque site="site_joint1_ph" name="torque1_ph"/>
    <torque site="site_joint2_ph" name="torque2_ph"/>
    <torque site="site_joint3_ph" name="torque3_ph"/>
    <torque site="site_joint4_ph" name="torque4_ph"/>
    <torque site="site_joint5_ph" name="torque5_ph"/>
    <torque site="site_joint6_ph" name="torque6_ph"/>
    <torque site="site_joint7_ph" name="torque7_ph"/>
  </sensor>
</mujoco>
