<?xml version="1.0" ?>
<!-- FR3 URDF with F_T_EE appended by positronic-franka.
     Used as default for real hardware datasets that don't have robot_meta stored natively.
     Generated from: Robot('172.168.0.2').get_robot_model() on 2026-03-16.

     Visual meshes added by positronic for 3D visualization in the dataset server.
     The <visual> elements reference STL filenames (e.g. "link0.stl") that match files in
     positronic/assets/fr3_collision/. These are Panda collision meshes from robosuite
     (franka_description package) — FR3 shares the same link geometry as Panda.
     Added via: xml.etree.ElementTree, iterating links and adding <visual><geometry><mesh>
     for each link with a matching .stl file in the assets directory. -->
<robot name="fr3">
  <link name="base">
      </link>
  <joint name="base_joint" type="fixed">
    <parent link="base"/>
    <child link="link0"/>
    <origin rpy="0 0 0" xyz="0 0 0"/>
  </joint>
  <link name="link0">
    <inertial>
      <origin rpy="0 0 0" xyz="-0.0172 0.0004 0.0745"/>
      <mass value="2.3966"/>
      <inertia ixx="0.009" ixy="0.0" ixz="0.002" iyy="0.0115" iyz="0.0" izz="0.0085"/>
    </inertial>
    <visual>
      <geometry>
        <mesh filename="link0.stl"/>
      </geometry>
    </visual>
  </link>
  <link name="link1">
    <inertial>
      <origin rpy="0 0 0" xyz="0.0000004128 -0.0181251324 -0.0386035970"/>
      <mass value="2.9274653454"/>
      <inertia ixx="0.023927316485107913" ixy="1.3317903455714081e-05" ixz="-0.00011404774918616684" iyy="0.0224821613275756" iyz="-0.0019950320628240115" izz="0.006350098258530016"/>
    </inertial>
    <visual>
      <geometry>
        <mesh filename="link1.stl"/>
      </geometry>
    </visual>
  </link>
  <joint name="joint1" type="revolute">
    <origin rpy="0 0 0" xyz="0 0 0.333"/>
    <parent link="link0"/>
    <child link="link1"/>
    <axis xyz="0 0 1"/>
    <limit effort="87.0" lower="-2.7437" upper="2.7437" velocity="2.62"/>
  </joint>
  <link name="link2">
    <inertial>
      <origin rpy="0 0 0" xyz="0.0031828864 -0.0743221644 0.0088146084"/>
      <mass value="2.9355370338"/>
      <inertia ixx="0.041938946257609425" ixy="0.00020257331521090626" ixz="0.004077784227179924" iyy="0.02514514885014724" iyz="-0.0042252158006570156" izz="0.06170214472888839"/>
    </inertial>
    <visual>
      <geometry>
        <mesh filename="link2.stl"/>
      </geometry>
    </visual>
  </link>
  <joint name="joint2" type="revolute">
    <origin rpy="-1.570796326794897 0 0" xyz="0 0 0"/>
    <parent link="link1"/>
    <child link="link2"/>
    <axis xyz="0 0 1"/>
    <limit effort="87.0" lower="-1.7837" upper="1.7837" velocity="2.62"/>
  </joint>
  <link name="link3">
    <inertial>
      <origin rpy="0 0 0" xyz="0.0407015686 -0.0048200565 -0.0289730823"/>
      <mass value="2.2449013699"/>
      <inertia ixx="0.02410142547240885" ixy="0.002404694559042109" ixz="-0.002856269270114313" iyy="0.01974053266708178" iyz="-0.002104212683891874" izz="0.019044494482244823"/>
    </inertial>
    <visual>
      <geometry>
        <mesh filename="link3.stl"/>
      </geometry>
    </visual>
  </link>
  <joint name="joint3" type="revolute">
    <origin rpy="1.570796326794897 0 0" xyz="0 -0.316 0"/>
    <parent link="link2"/>
    <child link="link3"/>
    <axis xyz="0 0 1"/>
    <limit effort="87.0" lower="-2.9007" upper="2.9007" velocity="2.62"/>
  </joint>
  <link name="link4">
    <inertial>
      <origin rpy="0 0 0" xyz="-0.0459100965 0.0630492960 -0.0085187868"/>
      <mass value="2.6155955791"/>
      <inertia ixx="0.03452998321913202" ixy="0.01322552265982813" ixz="0.01015142998484113" iyy="0.028881621933049058" iyz="-0.0009762833870704552" izz="0.04125471171146641"/>
    </inertial>
    <visual>
      <geometry>
        <mesh filename="link4.stl"/>
      </geometry>
    </visual>
  </link>
  <joint name="joint4" type="revolute">
    <origin rpy="1.570796326794897 0 0" xyz="0.0825 0 0"/>
    <parent link="link3"/>
    <child link="link4"/>
    <axis xyz="0 0 1"/>
    <limit effort="87.0" lower="-3.0421" upper="-0.1518" velocity="2.62"/>
  </joint>
  <link name="link5">
    <inertial>
      <origin rpy="0 0 0" xyz="-0.0016039605 0.0292536262 -0.0972965990"/>
      <mass value="2.3271207594"/>
      <inertia ixx="0.051610278463662895" ixy="-0.005715173387783472" ixz="-0.0035673167625872135" iyy="0.04787729713371481" iyz="0.010673985108535986" izz="0.016423625579357254"/>
    </inertial>
    <visual>
      <geometry>
        <mesh filename="link5.stl"/>
      </geometry>
    </visual>
  </link>
  <joint name="joint5" type="revolute">
    <origin rpy="-1.570796326794897 0 0" xyz="-0.0825 0.384 0"/>
    <parent link="link4"/>
    <child link="link5"/>
    <axis xyz="0 0 1"/>
    <limit effort="12.0" lower="-2.8065" upper="2.8065" velocity="5.26"/>
  </joint>
  <link name="link6">
    <inertial>
      <origin rpy="0 0 0" xyz="0.0597131221 -0.0410294666 -0.0101692726"/>
      <mass value="1.8170376524"/>
      <inertia ixx="0.005412333594383447" ixy="0.006193456360285834" ixz="0.0014219289306117652" iyy="0.014058329545509979" iyz="-0.0013140753741120031" izz="0.016080817924212554"/>
    </inertial>
    <visual>
      <geometry>
        <mesh filename="link6.stl"/>
      </geometry>
    </visual>
  </link>
  <joint name="joint6" type="revolute">
    <origin rpy="1.570796326794897 0 0" xyz="0 0 0"/>
    <parent link="link5"/>
    <child link="link6"/>
    <axis xyz="0 0 1"/>
    <limit effort="12.0" lower="0.5445" upper="4.5169" velocity="4.18"/>
  </joint>
  <link name="link7">
    <inertial>
      <origin rpy="0 0 0" xyz="0.0045225817 0.0086261921 -0.0161633251"/>
      <mass value="0.6271432862"/>
      <inertia ixx="0.00021092389150104718" ixy="-2.433299114461931e-05" ixz="4.564480393778983e-05" iyy="0.00017718568002411474" iyz="8.744070223226438e-05" izz="5.993190599659971e-05"/>
    </inertial>
    <visual>
      <geometry>
        <mesh filename="link7.stl"/>
      </geometry>
    </visual>
  </link>
  <joint name="joint7" type="revolute">
    <origin rpy="1.570796326794897 0 0" xyz="0.088 0 0"/>
    <parent link="link6"/>
    <child link="link7"/>
    <axis xyz="0 0 1"/>
    <limit effort="12.0" lower="-3.0159" upper="3.0159" velocity="5.26"/>
  </joint>
  <link name="link8"/>
  <joint name="joint8" type="fixed">
    <origin rpy="0 0 0" xyz="0 0 0.107"/>
    <parent link="link7"/>
    <child link="link8"/>
  </joint>

  <!-- WARNING: This link and joint were appended by positronic-franka,
       NOT part of the original URDF from libfranka getRobotModel().
       They encode F_T_EE (flange-to-end-effector transform) read from
       franka::RobotState at the time of this call, so that the URDF
       matches the full kinematic chain used by the driver's runtime IK. -->
  <link name="end_effector"/>
  <joint name="flange_to_end_effector" type="fixed">
    <parent link="link8"/>
    <child link="end_effector"/>
    <origin xyz="0 0 0.1033999994" rpy="3.141592654 -3.141592654 2.35619449"/>
  </joint>
</robot>
