<mujoco model="panda">
  <compiler angle="radian" autolimits="true"/>

  <default>
    <default class="panda">
      <joint armature="0.1" damping="1" axis="0 0 1" range="-2.8973 2.8973"/>
      <default class="finger">
        <joint axis="0 1 0" type="slide" range="0 0.04"/>
      </default>
    </default>
  </default>

  <worldbody>
    <body name="link0" childclass="panda">
      <inertial mass="0.629769" pos="-0.041018 -0.00014 0.049974"
        fullinertia="0.00315 0.00388 0.004285 8.2904e-7 0.00015 8.2299e-6"/>
      <body name="link1" pos="0 0 0.333">
        <inertial mass="4.970684" pos="0.003875 0.002081 -0.04762"
          fullinertia="0.70337 0.70661 0.0091170 -0.00013900 0.0067720 0.019169"/>
        <joint name="joint1"/>
        <body name="link2" quat="1 -1 0 0">
          <inertial mass="0.646926" pos="-0.003141 -0.02872 0.003495"
            fullinertia="0.0079620 2.8110e-2 2.5995e-2 -3.925e-3 1.0254e-2 7.04e-4"/>
          <joint name="joint2" range="-1.7628 1.7628"/>
          <body name="link3" pos="0 -0.316 0" quat="1 1 0 0">
            <inertial mass="3.228604" pos="2.7518e-2 3.9252e-2 -6.6502e-2"
              fullinertia="3.7242e-2 3.6155e-2 1.083e-2 -4.761e-3 -1.1396e-2 -1.2805e-2"/>
            <joint name="joint3"/>
            <body name="link4" pos="0.0825 0 0" quat="1 1 0 0">
              <inertial mass="3.587895" pos="-5.317e-2 1.04419e-1 2.7454e-2"
                fullinertia="2.5853e-2 1.9552e-2 2.8323e-2 7.796e-3 -1.332e-3 8.641e-3"/>
              <joint name="joint4" range="-3.0718 -0.0698"/>
              <body name="link5" pos="-0.0825 0.384 0" quat="1 -1 0 0">
                <inertial mass="1.225946" pos="-1.1953e-2 4.1065e-2 -3.8437e-2"
                  fullinertia="3.5549e-2 2.9474e-2 8.627e-3 -2.117e-3 -4.037e-3 2.29e-4"/>
                <joint name="joint5"/>
                <body name="link6" quat="1 1 0 0">
                  <inertial mass="1.666555" pos="6.0149e-2 -1.4117e-2 -1.0517e-2"
                    fullinertia="1.964e-3 4.354e-3 5.433e-3 1.09e-4 -1.158e-3 3.41e-4"/>
                  <joint name="joint6" range="-0.0175 3.7525"/>
                  <body name="link7" pos="0.088 0 0" quat="1 1 0 0">
                    <inertial mass="7.35522e-01" pos="1.0517e-2 -4.252e-3 6.1597e-2"
                      fullinertia="1.2516e-2 1.0027e-2 4.815e-3 -4.28e-4 -1.196e-3 -7.41e-4"/>
                    <joint name="joint7"/>
                    <body name="hand" pos="0 0 0.107" quat="0.9238795 0 0 -0.3826834">
                      <inertial mass="0.73" pos="-0.01 0 0.03" diaginertia="0.001 0.0025 0.0017"/>
                      <site name="end_effector" pos="0 0 0.0584"/>
                      <body name="left_finger" pos="0 0 0.0584">
                        <inertial mass="0.015" pos="0 0 0" diaginertia="2.375e-6 2.375e-6 7.5e-7"/>
                        <joint name="finger_joint1" class="finger"/>
                      </body>
                      <body name="right_finger" pos="0 0 0.0584" quat="0 0 0 1">
                        <inertial mass="0.015" pos="0 0 0" diaginertia="2.375e-6 2.375e-6 7.5e-7"/>
                        <joint name="finger_joint2" class="finger"/>
                      </body>
                    </body>
                  </body>
                </body>
              </body>
            </body>
          </body>
        </body>
      </body>
    </body>
  </worldbody>
</mujoco>
